Internal Server Error: /favicon.ico/
Traceback (most recent call last):
  File "/mnt/c/Users/noypa/Dev/TWC-ecommerce/src/lib/python3.10/site-packages/django/core/handlers/exception.py", line 47, in inner
    response = get_response(request)
  File "/mnt/c/Users/noypa/Dev/TWC-ecommerce/src/TWC/middleware.py", line 32, in __call__
    if request.subdomain:
AttributeError: 'WSGIRequest' object has no attribute 'subdomain'
Internal Server Error: /favicon.ico/
Traceback (most recent call last):
  File "/mnt/c/Users/noypa/Dev/TWC-ecommerce/src/lib/python3.10/site-packages/django/core/handlers/exception.py", line 47, in inner
    response = get_response(request)
  File "/mnt/c/Users/noypa/Dev/TWC-ecommerce/src/TWC/middleware.py", line 32, in __call__
    if request.subdomain:
AttributeError: 'WSGIRequest' object has no attribute 'subdomain'
"GET /favicon.ico/ HTTP/1.1" 500 64205
"GET /favicon.ico/ HTTP/1.1" 500 64205
You're accessing the development server over HTTPS, but it only supports HTTP.

You're accessing the development server over HTTPS, but it only supports HTTP.

You're accessing the development server over HTTPS, but it only supports HTTP.

You're accessing the development server over HTTPS, but it only supports HTTP.

Internal Server Error: /cart/checkout/complete/
Internal Server Error: /cart/checkout/complete/
"GET /cart/checkout/complete/ HTTP/1.1" 500 30
"GET /cart/checkout/complete/ HTTP/1.1" 500 30
Internal Server Error: /cart/checkout/complete/
Internal Server Error: /cart/checkout/complete/
"GET /cart/checkout/complete/ HTTP/1.1" 500 30
"GET /cart/checkout/complete/ HTTP/1.1" 500 30
Internal Server Error: /cart/checkout/complete/
Internal Server Error: /cart/checkout/complete/
"GET /cart/checkout/complete/ HTTP/1.1" 500 30
"GET /cart/checkout/complete/ HTTP/1.1" 500 30
Internal Server Error: /cart/checkout/complete/
Internal Server Error: /cart/checkout/complete/
"GET /cart/checkout/complete/ HTTP/1.1" 500 30
"GET /cart/checkout/complete/ HTTP/1.1" 500 30
Internal Server Error: /cart/checkout/complete/
Internal Server Error: /cart/checkout/complete/
"GET /cart/checkout/complete/ HTTP/1.1" 500 30
"GET /cart/checkout/complete/ HTTP/1.1" 500 30
Internal Server Error: /cart/checkout/complete/
Internal Server Error: /cart/checkout/complete/
"GET /cart/checkout/complete/ HTTP/1.1" 500 30
"GET /cart/checkout/complete/ HTTP/1.1" 500 30
Internal Server Error: /cart/checkout/complete/
Internal Server Error: /cart/checkout/complete/
"GET /cart/checkout/complete/ HTTP/1.1" 500 30
"GET /cart/checkout/complete/ HTTP/1.1" 500 30
Internal Server Error: /cart/checkout/complete/
Internal Server Error: /cart/checkout/complete/
"GET /cart/checkout/complete/ HTTP/1.1" 500 30
"GET /cart/checkout/complete/ HTTP/1.1" 500 30
Internal Server Error: /cart/checkout/complete/
Internal Server Error: /cart/checkout/complete/
"GET /cart/checkout/complete/ HTTP/1.1" 500 30
"GET /cart/checkout/complete/ HTTP/1.1" 500 30
Internal Server Error: /cart/checkout/complete/
Internal Server Error: /cart/checkout/complete/
"GET /cart/checkout/complete/ HTTP/1.1" 500 30
"GET /cart/checkout/complete/ HTTP/1.1" 500 30
Internal Server Error: /cart/checkout/complete/
Internal Server Error: /cart/checkout/complete/
"GET /cart/checkout/complete/ HTTP/1.1" 500 30
"GET /cart/checkout/complete/ HTTP/1.1" 500 30
Internal Server Error: /cart/checkout/complete/
Internal Server Error: /cart/checkout/complete/
"GET /cart/checkout/complete/ HTTP/1.1" 500 30
"GET /cart/checkout/complete/ HTTP/1.1" 500 30
You're accessing the development server over HTTPS, but it only supports HTTP.

You're accessing the development server over HTTPS, but it only supports HTTP.

You're accessing the development server over HTTPS, but it only supports HTTP.

You're accessing the development server over HTTPS, but it only supports HTTP.

Internal Server Error: /cart/submit-checkout/
Traceback (most recent call last):
  File "/mnt/c/Users/noypa/Dev/TWC-ecommerce/src/lib/python3.10/site-packages/django/core/handlers/exception.py", line 47, in inner
    response = get_response(request)
  File "/mnt/c/Users/noypa/Dev/TWC-ecommerce/src/lib/python3.10/site-packages/django/core/handlers/base.py", line 181, in _get_response
    response = wrapped_callback(request, *callback_args, **callback_kwargs)
  File "/mnt/c/Users/noypa/Dev/TWC-ecommerce/src/cart/views.py", line 424, in submit_checkout
    existing_order_items = order.orderitem_set.all()
AttributeError: 'NoneType' object has no attribute 'orderitem_set'
Internal Server Error: /cart/submit-checkout/
Traceback (most recent call last):
  File "/mnt/c/Users/noypa/Dev/TWC-ecommerce/src/lib/python3.10/site-packages/django/core/handlers/exception.py", line 47, in inner
    response = get_response(request)
  File "/mnt/c/Users/noypa/Dev/TWC-ecommerce/src/lib/python3.10/site-packages/django/core/handlers/base.py", line 181, in _get_response
    response = wrapped_callback(request, *callback_args, **callback_kwargs)
  File "/mnt/c/Users/noypa/Dev/TWC-ecommerce/src/cart/views.py", line 424, in submit_checkout
    existing_order_items = order.orderitem_set.all()
AttributeError: 'NoneType' object has no attribute 'orderitem_set'
"POST /cart/submit-checkout/ HTTP/1.1" 500 69349
"POST /cart/submit-checkout/ HTTP/1.1" 500 69349
Internal Server Error: /cart/submit-checkout/
Traceback (most recent call last):
  File "/mnt/c/Users/noypa/Dev/TWC-ecommerce/src/lib/python3.10/site-packages/django/core/handlers/exception.py", line 47, in inner
    response = get_response(request)
  File "/mnt/c/Users/noypa/Dev/TWC-ecommerce/src/lib/python3.10/site-packages/django/core/handlers/base.py", line 181, in _get_response
    response = wrapped_callback(request, *callback_args, **callback_kwargs)
  File "/mnt/c/Users/noypa/Dev/TWC-ecommerce/src/cart/views.py", line 425, in submit_checkout
    existing_order_items = order.orderitem_set.all()
AttributeError: 'NoneType' object has no attribute 'orderitem_set'
Internal Server Error: /cart/submit-checkout/
Traceback (most recent call last):
  File "/mnt/c/Users/noypa/Dev/TWC-ecommerce/src/lib/python3.10/site-packages/django/core/handlers/exception.py", line 47, in inner
    response = get_response(request)
  File "/mnt/c/Users/noypa/Dev/TWC-ecommerce/src/lib/python3.10/site-packages/django/core/handlers/base.py", line 181, in _get_response
    response = wrapped_callback(request, *callback_args, **callback_kwargs)
  File "/mnt/c/Users/noypa/Dev/TWC-ecommerce/src/cart/views.py", line 425, in submit_checkout
    existing_order_items = order.orderitem_set.all()
AttributeError: 'NoneType' object has no attribute 'orderitem_set'
"POST /cart/submit-checkout/ HTTP/1.1" 500 69349
"POST /cart/submit-checkout/ HTTP/1.1" 500 69349
Internal Server Error: /cart/submit-checkout/
Traceback (most recent call last):
  File "/mnt/c/Users/noypa/Dev/TWC-ecommerce/src/lib/python3.10/site-packages/django/core/handlers/exception.py", line 47, in inner
    response = get_response(request)
  File "/mnt/c/Users/noypa/Dev/TWC-ecommerce/src/lib/python3.10/site-packages/django/core/handlers/base.py", line 181, in _get_response
    response = wrapped_callback(request, *callback_args, **callback_kwargs)
  File "/mnt/c/Users/noypa/Dev/TWC-ecommerce/src/cart/views.py", line 435, in submit_checkout
    return redirect('checkout_complete')
  File "/mnt/c/Users/noypa/Dev/TWC-ecommerce/src/lib/python3.10/site-packages/django/shortcuts.py", line 41, in redirect
    return redirect_class(resolve_url(to, *args, **kwargs))
  File "/mnt/c/Users/noypa/Dev/TWC-ecommerce/src/lib/python3.10/site-packages/django/shortcuts.py", line 130, in resolve_url
    return reverse(to, args=args, kwargs=kwargs)
  File "/mnt/c/Users/noypa/Dev/TWC-ecommerce/src/lib/python3.10/site-packages/django/urls/base.py", line 86, in reverse
    return resolver._reverse_with_prefix(view, prefix, *args, **kwargs)
  File "/mnt/c/Users/noypa/Dev/TWC-ecommerce/src/lib/python3.10/site-packages/django/urls/resolvers.py", line 694, in _reverse_with_prefix
    raise NoReverseMatch(msg)
django.urls.exceptions.NoReverseMatch: Reverse for 'checkout_complete' not found. 'checkout_complete' is not a valid view function or pattern name.
Internal Server Error: /cart/submit-checkout/
Traceback (most recent call last):
  File "/mnt/c/Users/noypa/Dev/TWC-ecommerce/src/lib/python3.10/site-packages/django/core/handlers/exception.py", line 47, in inner
    response = get_response(request)
  File "/mnt/c/Users/noypa/Dev/TWC-ecommerce/src/lib/python3.10/site-packages/django/core/handlers/base.py", line 181, in _get_response
    response = wrapped_callback(request, *callback_args, **callback_kwargs)
  File "/mnt/c/Users/noypa/Dev/TWC-ecommerce/src/cart/views.py", line 435, in submit_checkout
    return redirect('checkout_complete')
  File "/mnt/c/Users/noypa/Dev/TWC-ecommerce/src/lib/python3.10/site-packages/django/shortcuts.py", line 41, in redirect
    return redirect_class(resolve_url(to, *args, **kwargs))
  File "/mnt/c/Users/noypa/Dev/TWC-ecommerce/src/lib/python3.10/site-packages/django/shortcuts.py", line 130, in resolve_url
    return reverse(to, args=args, kwargs=kwargs)
  File "/mnt/c/Users/noypa/Dev/TWC-ecommerce/src/lib/python3.10/site-packages/django/urls/base.py", line 86, in reverse
    return resolver._reverse_with_prefix(view, prefix, *args, **kwargs)
  File "/mnt/c/Users/noypa/Dev/TWC-ecommerce/src/lib/python3.10/site-packages/django/urls/resolvers.py", line 694, in _reverse_with_prefix
    raise NoReverseMatch(msg)
django.urls.exceptions.NoReverseMatch: Reverse for 'checkout_complete' not found. 'checkout_complete' is not a valid view function or pattern name.
"POST /cart/submit-checkout/ HTTP/1.1" 500 88737
"POST /cart/submit-checkout/ HTTP/1.1" 500 88737
Internal Server Error: /cart/submit-checkout/
Traceback (most recent call last):
  File "/mnt/c/Users/noypa/Dev/TWC-ecommerce/src/lib/python3.10/site-packages/django/core/handlers/exception.py", line 47, in inner
    response = get_response(request)
  File "/mnt/c/Users/noypa/Dev/TWC-ecommerce/src/lib/python3.10/site-packages/django/core/handlers/base.py", line 181, in _get_response
    response = wrapped_callback(request, *callback_args, **callback_kwargs)
  File "/mnt/c/Users/noypa/Dev/TWC-ecommerce/src/cart/views.py", line 427, in submit_checkout
    existing_order_items = order.orderitem_set.all()
AttributeError: 'NoneType' object has no attribute 'orderitem_set'
Internal Server Error: /cart/submit-checkout/
Traceback (most recent call last):
  File "/mnt/c/Users/noypa/Dev/TWC-ecommerce/src/lib/python3.10/site-packages/django/core/handlers/exception.py", line 47, in inner
    response = get_response(request)
  File "/mnt/c/Users/noypa/Dev/TWC-ecommerce/src/lib/python3.10/site-packages/django/core/handlers/base.py", line 181, in _get_response
    response = wrapped_callback(request, *callback_args, **callback_kwargs)
  File "/mnt/c/Users/noypa/Dev/TWC-ecommerce/src/cart/views.py", line 427, in submit_checkout
    existing_order_items = order.orderitem_set.all()
AttributeError: 'NoneType' object has no attribute 'orderitem_set'
"POST /cart/submit-checkout/ HTTP/1.1" 500 69391
"POST /cart/submit-checkout/ HTTP/1.1" 500 69391
